Workbook

Sheet Insumo
A1: 3 - 705
A2: Cod. Insumo | B2: Desc. Insumo | C2: Unid. Insumo | D2: Preco Insumo | E2: Preco Improd.
A3: IE0001 | B3: TRATOR DE ESTEIRAS : NEW HOLLAND : 7D - COM LÂMINA | C3: H | D3: 123.7328 | E3: 20.5962
A4: IE0002 | B4: TRATOR DE ESTEIRAS : CATERPILLAR : D6N - COM LÂMINA | C4: H | D4: 178.5126 | E4: 20.5962
A5: IE0003 | B5: TRATOR DE ESTEIRAS : CATERPILLAR : D8T - COM LÂMINA | C5: H | D5: 392.9867 | E5: 20.5962
A6: IE0005 | B6: MOTOSCRAPER : CATERPILLAR : 621H - | C6: H | D6: 438.2318 | E6: 20.5962
A7: IE0006 | B7: MOTONIVELADORA : CATERPILLAR : 120K - | C7: H | D7: 153.4794 | E7: 20.5962
A8: IE0007 | B8: TRATOR AGRÍCOLA : MASSEY FERGUSON : MF 4291/4 449A - | C8: H | D8: 72.8389 | E8: 15.4471
A9: IE0009 | B9: CARREGADEIRA DE PNEUS : CATERPILLAR : 924H - 1,80 M3 | C9: H | D9: 123.8771 | E9: 20.5962
A10: IE0010 | B10: CARREGADEIRA DE PNEUS : CATERPILLAR : 950H - 3,3 M3 | C10: H | D10: 204.9757 | E10: 20.5962
A11: IE0011 | B11: RETROESCAVADEIRA : MASSEY FERGUSON : MF-86HS - DE | C11: H | D11: 77.4726 | E11: 20.5962
A12: IE0013 | B12: ROLO COMPACTADOR : DYNAPAC : CA-250-P - PÉ DE CARNEIRO | C12: H | D12: 116.1012 | E12: 15.4471
A13: IE0014 | B13: TRATOR DE ESTEIRAS : CATERPILLAR : D8T - COM | C13: H | D13: 403.4299 | E13: 20.5962
A14: IE0015 | B14: TRATOR DE ESTEIRAS : CATERPILLAR : D8T - COM | C14: H | D14: 195.71 | E14: 20.6
... A227: IH0000 | B227: SALÁRIO MÍNIMO | C227: H | D227: 7.2522 | E227: 0
A228: IH0001 | B228: CAPATAZ | C228: H | D228: 14
A229: IH0002 | B229: MAESTRO 1° | C229: H | D229: 12
A230: IH0003 | B230: MAESTRO 2° | C230: H | D230: 10
A231: IH0004 | B231: AYUDANTE | C231: H | D231: 9
A232: IH0301 | B232: MOTORISTA DE VEÍCULO LEVE | C232: H | D232: 12.1111 | E232: 0
A233: IH0302 | B233: MOTORISTA DE CAMINHÃO | C233: H | D233: 15.8097 | E233: 0
A234: IH0303 | B234: MOTORISTA DE VEÍCULO ESPECIAL | C234: H | D234: 16.2449 | E234: 0
A235: IH0311 | B235: OPERADOR DE EQUIPAMENTO LEVE 1 | C235: H | D235: 15.4471 | E235: 0
A236: IH0312 | B236: OPERADOR DE EQUIPAMENTO LEVE 2 | C236: H | D236: 15.4471 | E236: 0
A237: IH0313 | B237: OPERADOR DE EQUIP. PESADO | C237: H | D237: 20.5962 | E237: 0
A238: IH0314 | B238: OPERADOR DE EQUIP. ESPECIAL | C238: H | D238: 20.6687 | E238: 0
A239: IH0401 | B239: PRÉ-MARCADOR | C239: H | D239: 12.4737 | E239: 0
A240: IH0501 | B240: ENCARREGADO DE TURMA | C240: H | D240: 26.7605 | E240: 0
A241: IH0511 | B241: ENCARREG. DE PAVIMENTAÇÃO | C241: H | D241: 38.5816 | E241: 0
A242: IH0512 | B242: ENCARREGADO DE BRITAGEM | C242: H | D242: 38.5816 | E242: 0
A243: IH0601 | B243: BLASTER | C243: H | D243: 26.7605 | E243: 0
... A260: IM0005 | B260: ENERGIA ELÉTRICA | C260: KWH | D260: 0.48 | E260: 0
A261: IM0006 | B261: LUBRIFICANTES Y GRASAS | C261: KG | D261: =+D257*2.5 -> 5.725 | E261: 0
A262: IM0101 | B262: CIMENTO ASFÁLTICO CAP 50/70 | C262: T | D262: 0 | E262: 0
A263: IM0102 | B263: CIMENTO ASFÁLTICO CAP 30/45 | C263: T | D263: 0 | E263: 0
A264: IM0103 | B264: ASFALTO DILUÍDO CM-30 | C264: T | D264: 0 | E264: 0
A265: IM0104 | B265: EMULSÃO ASFÁLTICA RR-1C | C265: T | D265: 0 | E265: 0
A266: IM0105 | B266: EMULSÃO ASFÁLTICA RR-2C | C266: T | D266: 0 | E266: 0
A267: IM0106 | B267: EMULSÃO ASFALTICA RR1C C/ POLÍMERO | C267: T | D267: 0 | E267: 0
A268: IM0107 | B268: EMULSÃO ASFÁLTICA RM-1C | C268: T | D268: 0 | E268: 0
...

Sheet CP. Auxiliar
A1: 4-1196
A2: Cod. Composicao | B2: Descricao Completa | C2: Unid. Comp | D2: Prod. Equipe | E2: Perc. Ferramenta | F2: Cod. Insumo | G2: Qtde Equip. | H2: Indice | I2: Indice Improdutivo | J2: DMT (Transp) | K2: Consumo (Transp) | L2: Unid. Insumo | M2: Desc. Insumo
A3: CA0001 | B3: CUADRILLA ESCAVACION 1 Turno per dia | C3: H | D3: 1 | F3: XXXX | H3: =0.3/10 -> 0.03 | L3: H | M3: CAPATAZ
F4: XXXX | H4: =0.7/10 -> 0.07 | L4: H | M4: MAESTRO 1°
F5: XXXX | H5: =3/10 -> 0.3 | L5: H | M5: MAESTRO 2°
F6: XXXX | H6: =6/10 -> 0.6 | L6: H | M6: AYUDANTE
A7: CA0002 | B7: CUADRILLA ESCAVACION 2 Turno por dia | F7: XXXX | H7: =0.3/10 -> 0.03 | L7: H | M7: CAPATAZ
F8: XXXX | H8: =0.7/10 -> 0.07 | L8: H | M8: MAESTRO 1°
F9: XXXX | H9: =3/10 -> 0.3 | L9: H | M9: MAESTRO 2°
F10: XXXX | H10: =6/10 -> 0.6 | L10: H | M10: AYUDANTE
A11: CA0003 | B11: CUADRILLA CONCRETO 1 Turno por dia | F11: XXXX | H11: 0.1 | L11: H | M11: CAPATAZ
F12: XXXX | H12: 0.2 | L12: H | M12: MAESTRO 1°
F13: XXXX | H13: 0.3 | L13: H | M13: MAESTRO 2°
F14: XXXX | H14: 0.4 | L14: H | M14: AYUDANTE
A15: CA0004 | B15: CUADRILLA CONCRETO 2 Turno por dia | F15: XXXX | H15: 0.1 | L15: H | M15: CAPATAZ
F16: XXXX | H16: 0.2 | L16: H | M16: MAESTRO 1°
F17: XXXX | H17: 0.3 | L17: H | M17: MAESTRO 2°
F18: XXXX | H18: 0.4 | L18: H | M18: AYUDANTE
A19: CA0005 | B19: CUADRILLA FORMALETA 1 Turno por dia | F19: XXXX | H19: 0.1 | L19: H | M19: CAPATAZ
F20: XXXX | H20: 0.3 | L20: H | M20: MAESTRO 1°
F21: XXXX | H21: 0.3 | L21: H | M21: MAESTRO 2°
F22: XXXX | H22: 0.3 | L22: H | M22: AYUDANTE
A23: CA0006 | B23: CUADRILLA FORMALETA 2 Turno por dia | F23: XXXX | H23: 0.1 | L23: H | M23: CAPATAZ
F24: XXXX | H24: 0.3 | L24: H | M24: MAESTRO 1°
F25: XXXX | H25: 0.3 | L25: H | M25: MAESTRO 2°
F26: XXXX | H26: 0.3 | L26: H | M26: AYUDANTE
A27: CA0007 | B27: CUADRILLA ACERO 1 Turno por dia | F27: XXXX | H27: 0.1 | L27: H | M27: CAPATAZ
F28: XXXX | H28: 0.2 | L28: H | M28: MAESTRO 1°
F29: XXXX | H29: 0.4 | L29: H | M29: MAESTRO 2°
F30: XXXX | H30: 0.3 | L30: H | M30: AYUDANTE
A31: CA0008 | B31: CUADRILLA ACERO 2 Turno por dia | F31: XXXX | H31: 0.1 | L31: H | M31: CAPATAZ
F32: XXXX | H32: 0.2 | L32: H | M32: MAESTRO 1°
F33: XXXX | H33: 0.4 | L33: H | M33: MAESTRO 2°
F34: XXXX | H34: 0.3 | L34: H | M34: AYUDANTE
A35: CA0009 | B35: CUADRILLA VARIOS 1 Turno por dia | F35: XXXX | H35: 0.1 | L35: H | M35: CAPATAZ
F36: XXXX | H36: 0.2 | L36: H | M36: MAESTRO 1°
F37: XXXX | H37: 0.2 | L37: H | M37: MAESTRO 2°
F38: XXXX | H38: 0.5 | L38: H | M38: AYUDANTE
A39: CA0010 | B39: CUADRILLA VARIOS 2 Turno por dia | F39: XXXX | H39: 0.1 | L39: H | M39: CAPATAZ
F40: XXXX | H40: 0.2 | L40: H | M40: MAESTRO 1°
...

Sheet CP. Principal
A2: Cod. Composicao | B2: Descricao Completa | C2: Unid. Comp | D2: Prod. Equipe | E2: Perc. Ferramenta | F2: Cod. Insumo | G2: código | H2: Qtde Equip. | I2: Indice | J2: Indice Improdutivo | K2: DMT (Transp) | L2: Consumo (Transp) | M2: Unid. Insumo | N2: Desc. Insumo | O2: NOTE
A4: CB0001 | B4: 25.6 BARRA DE ACO CA-50 | C4: KG | D4: 1 | F4: XXXX | I4: 1.05 | N4: ACERO CORTADO E DOBLADO PER PANTALLAS IN SITE C-50 | O4: doca seca - SOLO OPERAZIONI DI SCARICO POSA NEL COSTO DEL DIAFRAMMA
F5: =+'CP. Auxiliar'!A31 -> CA0008 | I5: =+I6*10*1.2 -> 0.0010152 | N5: =+'CP. Auxiliar'!B31 -> CUADRILLA ACERO 2 Turno por dia
F6: XXXX | G6: IE5068 | I6: =0.0846/1000 -> 8.46e-05 | J6: =(I5/10)-I6 -> 1.692e-05 | N6: GRU CINGOLATA 50 TON
F7: XXXX | G7: IH1021 | I7: =I6+J6 -> 0.00010152 | N7: OPERADOR DE EQUIP. PESADO 2 turno por dia
F8: =+'CP. Auxiliar'!A73 -> CA0051 | G8: IE5077 | I8: 1.5e-05 | J8: =+I8 -> 1.5e-05 | M8: HR | N8: =+'CP. Auxiliar'!B73 -> ILLUMINAZIONE
A9: CB0002 | B9: 5.13 BARRA DE ACO CA-50 | C9: KG | F9: XXXX | I9: =1.05*S10 -> 0.525 | N9: ACERO CORTADO E DOBLADO PER PANTALLAS IN SITE C-50 | O9: rampe di accesso paratie | S9: % PARATIE | T9: % CLS NORMALE
F10: =+F5 -> CA0008 | I10: =+I11*10*1.2 -> 0.0005076 | N10: =+N5 -> CUADRILLA ACERO 2 Turno por dia | S10: 0.5 | T10: 0.5
F11: XXXX | G11: IE5068 | I11: =(0.0846/1000)*S10 -> 4.23e-05 | J11: =(I10/10)-I11 -> 8.46e-06 | N11: GRU CINGOLATA 50 TON
F12: XXXX | G12: IH1021 | I12: =I11+J11 -> 5.076e-05 | N12: OPERADOR DE EQUIP. PESADO 2 turno por dia
F13: =+F8 -> CA0051 | G13: IE5077 | I13: 1.5e-05 | J13: =+I13 -> 1.5e-05 | M13: HR | N13: =+N8 -> ILLUMINAZIONE
F14: XXXX | I14: =1.05*T10 -> 0.525 | N14: ACERO CORTADO E DOBLADO IN SITE C-50 | O14: acciao per calcerstruzzi normali
F15: =+'CP. Auxiliar'!A31 -> CA0008 | I15: =(100*T10)/1000 -> 0.05 | N15: =+N10 -> CUADRILLA ACERO 2 Turno por dia
F16: XXXX | G16: IE5010 | I16: =((0.29+0.0846+0.0846)/1000)*T10 -> 0.0002296 | J16: =+I17-I16 -> 0.0047704 | N16: Grua da 35 Ton
F17: XXXX | G17: IH1021 | I17: =I15/10 -> 0.005 | N17: OPERADOR DE EQUIP. PESADO 2 turno por dia
F18: XXXX | G18: IE5076 | I18: =(0.17/1000)*T10 -> 8.5e-05 | J18: =+I19-I18 -> 0.002415 | N18: Camion con baja da 40 ton
F19: XXXX | G19: IH1021 | I19: =(I15/10)*0.5 -> 0.0025 | N19: OPERADOR DE EQUIP. PESADO 2 turno por dia | O19: Considero che il camion al 50 % perché farà altri lavori
F20: XXXX | G20: IE5049 | I20: =(0.31/1000)*T10 -> 0.000155 | J20: =(I15/10)-I20 -> 0.004845 | N20: Saldadora diesel 550 AMP
F21: =+'CP. Auxiliar'!A73 -> CA0051 | G21: IE5077 | I21: 1.5e-05 | J21: =+I21 -> 1.5e-05 | M21: HR | N21: =+'CP. Auxiliar'!B73 -> ILLUMINAZIONE
A22: CB0003 | B22: 6.11 BARRA DE ACO CA - 50 | C22: KG | F22: XXXX | I22: 1.05 | N22: ACERO CORTADO E DOBLADO PER PANTALLAS IN SITE C-50
F23: =+'CP. Auxiliar'!A31 -> CA0008 | I23: =100/1000 -> 0.1 | N23: =+'CP. Auxiliar'!B31 -> CUADRILLA ACERO 2 Turno por dia
F24: XXXX | G24: IE5010 | I24: =(0.29+0.0846+0.0846)/1000 -> 0.0004592 | J24: =+I25-I24 -> 0.0095408 | N24: Grua da 35 Ton
F25: XXXX | G25: IH1021 | I25: =I23/10 -> 0.01 | N25: OPERADOR DE EQUIP. PESADO 2 turno por dia
F26: XXXX | G26: IE5076 | I26: =(0.17/1000) -> 0.00017 | J26: =+I27-I26 -> 0.00483 | N26: Camion con baja da 40 ton
F27: XXXX | G27: IH1021 | I27: =(I23/10)*0.5 -> 0.005 | N27: OPERADOR DE EQUIP. PESADO 2 turno por dia | O27: Considero che il camion al 50 % perché farà altri lavori
F28: XXXX | G28: IE5049 | I28: =(0.31/1000) -> 0.00031 | J28: =(I23/10)-I28 -> 0.00969 | N28: Saldadora diesel 550 AMP
F29: =+'CP. Auxiliar'!A73 -> CA0051 | G29: IE5077 | I29: 1.5e-05 | J29: =+I29 -> 1.5e-05 | M29: HR | N29: ILLUMINAZIONE
A30: CB0004 | B30: 25.7 BARRA DE ACO CA - 60 | C30: KG | F30: XXXX | I30: 1.05 | N30: ACERO CORTADO E DOBLADO IN SITE C-60
F31: =+'CP. Auxiliar'!A39 -> CA0010 | I31: =100/1000 -> 0.1 | N31: =+'CP. Auxiliar'!B39 -> CUADRILLA VARIOS 2 Turno por dia
F32: XXXX | G32: IE5010 | I32: =(0.29+0.0846+0.0846)/1000 -> 0.0004592 | J32: =+I33-I32 -> 0.0095408 | N32: Grua da 35 Ton
F33: XXXX | G33: IH1021 | I33: =I31/10 -> 0.01 | N33: OPERADOR DE EQUIP. PESADO 2 turno por dia
F34: XXXX | G34: IE5076 | I34: =(0.17/1000) -> 0.00017 | J34: =+I35-I34 -> 0.00483 | N34: Camion con baja da 40 ton
F35: XXXX | G35: IH1021 | I35: =(I31/10)*0.5 -> 0.005 | N35: OPERADOR DE EQUIP. PESADO 2 turno por dia | O35: Considero che il camion al 50 % perché farà altri lavori
F36: XXXX | G36: IE5049 | I36: =(0.31/1000) -> 0.00031 | J36: =(I31/10)-I36 -> 0.00969 | N36: Saldadora diesel 550 AMP
F37: =+'CP. Auxiliar'!A73 -> CA0051 | G37: IE5077 | I37: 1.5e-05 | J37: =+I37 -> 1.5e-05 | M37: HR | N37: ILLUMINAZIONE
A38: CB0005 | B38: 6.12 BARRA DE ACO CA - 60 | C38: KG | F38: XXXX | I38: 1.05 | N38: ACERO CORTADO E DOBLADO IN SITE C-60
F39: =+'CP. Auxiliar'!A31 -> CA0008 | I39: =100/1000 -> 0.1 | N39: =+'CP. Auxiliar'!B31 -> CUADRILLA ACERO 2 Turno por dia
F40: XXXX | G40: IE5010 | I40: =(0.29+0.0846+0.0846)/1000 -> 0.0004592 | J40: =+I41-I40 -> 0.0095408 | N40: Grua da 35 Ton
F41: XXXX | G41: IH1021 | I41: =I39/10 -> 0.01 | N41: OPERADOR DE EQUIP. PESADO 2 turno por dia
F42: XXXX | G42: IE5076 | I42: =(0.17/1000) -> 0.00017 | J42: =+I43-I42 -> 0.00483 | N42: Camion con baja da 40 ton | O42: Considero che il camion al 50 % perché farà altri lavori
...

Sheet Planilha de serviços
A1: 8-863 | B1: A - F
A2: DATA BASE: SETEMBRO/2013
A3: LPI 001/2013
A4: ORÇAMENTO ESTIMATIVO DE SERVIÇOS E PREÇOS
A5: OBRAS DE IMPLANTAÇÃO DO SUBMERSO - TÚNEL SANTOS - GUARUJÁ, INTEGRANTE DO PROJETO DE MELHORIA LOGÍSTICA E DE MOBILIDADE URBANA ENTRE SANTOS E GUARUJÁ.
A8: ITEM | B8: CPU | C8: DESCRIÇÃO COMPLETA | D8: UNIDADE | E8: QUANT. | F8: PREÇO UNITÁRIO | H8: PREÇO UNITÁRIO DERSA | I8: PREÇO TOTAL | J8: ITEM | K8: SUB GRUPO | L8: CÓDIGO DERSA
C9: ACESSOS - LADO SANTOS E GUARUJÁ
A10: 1 | C10: =K10 -> SERVIÇOS PRELIMINARES | J10: ACESSOS - LADO SANTOS E GUARUJÁ | K10: SERVIÇOS PRELIMINARES | L10: 21
A11: 1.1 | C11: REMOÇÃO CERCA ARAME, INCLUSIVE TRANSPORTE | D11: m | E11: 400 | H11: 12.03 | I11: =E11*H11 -> 4812 | J11: ACESSOS - LADO SANTOS E GUARUJÁ | K11: SERVIÇOS PRELIMINARES | L11: 21.03.01
A12: 1.2 | C12: REMOCAO DE DEFENSA METALICA SIMPLES | D12: m | E12: 200 | H12: 43.91 | I12: =E12*H12 -> 8782 | J12: ACESSOS - LADO SANTOS E GUARUJÁ | K12: SERVIÇOS PRELIMINARES | L12: 21.03.02
A13: 1.3 | C13: REMOÇÃO E TRANSPORTE DE GUIA PRÉ-MOLDADA | D13: m | E13: 18670.46 | H13: 17.64 | I13: =E13*H13 -> 329346.91 | J13: ACESSOS - LADO SANTOS E GUARUJÁ | K13: SERVIÇOS PRELIMINARES | L13: 21.03.08
A14: 1.4 | C14: DEMOLIÇÃO DE CONCRETO ARMADO | D14: m3 | E14: 39039.41 | H14: 294.37 | I14: =E14*H14 -> 11492031 | J14: ACESSOS - LADO SANTOS E GUARUJÁ | K14: SERVIÇOS PRELIMINARES | L14: 21.88.0.,01
A15: 1.5 | C15: DEMOLIÇÃO DE CONCRETO SIMPLES | D15: m3 | E15: 63709.51 | H15: 154.29 | I15: =(E15*H15)-0.008 -> 9829740.3 | J15: ACESSOS - LADO SANTOS E GUARUJÁ | K15: SERVIÇOS PRELIMINARES | L15: 21.88.05.02
A16: 1.6 | C16: DEMOLIÇÃO DE EDIFICAÇÃO EM ALVENARIA | D16: m2 | E16: 66412.68 | H16: 35.6 | I16: =E16*H16 -> 2364291.4 | J16: ACESSOS - LADO SANTOS E GUARUJÁ | K16: SERVIÇOS PRELIMINARES | L16: 21.88.05.05
A17: 1.7 | C17: DEMOLIÇÃO DE EDIFICAÇÃO EM MADEIRA | D17: m2 | E17: 34516.27 | H17: 13.19 | I17: =E17*H17 -> 455269.6 | J17: ACESSOS - LADO SANTOS E GUARUJÁ | K17: SERVIÇOS PRELIMINARES | L17: 21.88.05.06
A18: 1.8 | C18: DEMOLIÇÃO DE PAVIMENTO FLEXIVEL | D18: m3 | E18: 41618.81 | H18: 18.52 | I18: =E18*H18 -> 770780.36 | J18: ACESSOS - LADO SANTOS E GUARUJÁ | K18: SERVIÇOS PRELIMINARES | L18: 21.88.05.07
A19: 1.9 | C19: MURO DE FECHAMENTO COM PLACAS E MOURÕES PRÉ-MOLDADO H=2,00 m | D19: m | E19: 100 | H19: 125.96 | I19: =E19*H19 -> 12596 | J19: ACESSOS - LADO SANTOS E GUARUJÁ | K19: SERVIÇOS PRELIMINARES | L19: 21.88.19.01
A20: 1.10 | C20: TRANSPORTE DE MATERIAL CLASSE IIA e IIB PARA BOTA-FORA ESPECIAL | D20: ton x km | E20: 7813575.8 | H20: 1.24 | I20: =E20*H20 -> 9688834 | J20: ACESSOS - LADO SANTOS E GUARUJÁ | K20: SERVIÇOS PRELIMINARES | L20: 21.88.19.08.03
A21: 1.11 | C21: BRITAGEM DE MATERIAL DE DEMOLIÇÃO | D21: m3 | E21: 101234.38 | H21: 50.86 | I21: =E21*H21 -> 5148780.6 | J21: ACESSOS - LADO SANTOS E GUARUJÁ | K21: SERVIÇOS PRELIMINARES | L21: 21.88.20.01
A22: 1.12 | C22: DEPOSIÇÃO DE MATERIAL CLASSE IIA, EM BOTA-FORA ESPECIAL | D22: ton | E22: 151405.85 | H22: 94.5 | I22: =E22*H22 -> 14307853 | J22: ACESSOS - LADO SANTOS E GUARUJÁ | K22: SERVIÇOS PRELIMINARES | L22: 21.88.21.02
A23: 1.13 | C23: DEPOSIÇÃO DE MATERIAL CLASSE IIB, EM BOTA-FORA ESPECIAL | D23: ton | E23: 151401.71 | H23: 67.5 | I23: =E23*H23 -> 10219615 | J23: ACESSOS - LADO SANTOS E GUARUJÁ | K23: SERVIÇOS PRELIMINARES | L23: 21.88.21.03
A24: 1.14 | C24: TRANSPORTE DE MATERIAL DE DEMOLIÇÃO ATÉ 5 KM | D24: m3 x km | E24: 506171.91 | H24: 1.71 | I24: =E24*H24 -> 865553.97 | J24: ACESSOS - LADO SANTOS E GUARUJÁ | K24: SERVIÇOS PRELIMINARES | L24: 22.88.03.03
A25: 2 | C25: =K25 -> TERRAPLENAGEM | J25: ACESSOS - LADO SANTOS E GUARUJÁ | K25: TERRAPLENAGEM | L25: 22
A26: 2.1 | C26: LIMPEZA ÁRVORES DE TERRENO SEM DESTOCAMENTO DE ÁRVORES | D26: m2 | E26: 181263 | H26: 0.28 | I26: =E26*H26 -> 50753.64 | J26: ACESSOS - LADO SANTOS E GUARUJÁ | K26: TERRAPLENAGEM | L26: 22.01.01
A27: 2.2 | B27: CB0001 | C27: ESCAVAÇÃO E CARGA DE MATERIAL DE 1ª/2ª CATEGORIA | D27: m3 | E27: 49049.95 | H27: 4.9 | I27: =E27*H27 -> 240344.76 | J27: ACESSOS - LADO SANTOS E GUARUJÁ | K27: TERRAPLENAGEM | L27: 22.02.01
A28: 2.3 | C28: ESCAVAÇÃO E CARGA DE MATERIAL DE 2ª CATEGORIA COM RIPPER | D28: m3 | E28: 691.55 | H28: 5.44 | I28: =E28*H28 -> 3762.032 | J28: ACESSOS - LADO SANTOS E GUARUJÁ | K28: TERRAPLENAGEM | L28: 22.02.02
A29: 2.4 | C29: CARGA DE MATERIAL DE LIMPEZA | D29: m3 | E29: 36252.6 | H29: 2.26 | I29: =E29*H29 -> 81930.876 | J29: ACESSOS - LADO SANTOS E GUARUJÁ | K29: TERRAPLENAGEM | L29: 22.02.06
A30: 2.5 | C30: TRANSPORTE DE MATERIAL DE 1ª/2ª CATEGORIA ATÉ 1 km | D30: m3 x km | E30: 729.26 | H30: 3.74 | I30: =E30*H30 -> 2727.4324 | J30: ACESSOS - LADO SANTOS E GUARUJÁ | K30: TERRAPLENAGEM | L30: 22.03.01
A31: 2.6 | C31: TRANSPORTE DE MATERIAL DE 1ª/2ª CATEGORIA ATÉ 2 km | D31: m3 x km | E31: 2187.76 | H31: 2.2 | I31: =E31*H31 -> 4813.072 | J31: ACESSOS - LADO SANTOS E GUARUJÁ | K31: TERRAPLENAGEM | L31: 22.03.02
A32: 2.7 | C32: TRANSPORTE DE MATERIAL DE 1ª/2ª CATEGORIA ATÉ 5 km | D32: m3 x km | E32: 3000.93 | H32: 1.71 | I32: =E32*H32 -> 5131.5903 | J32: ACESSOS - LADO SANTOS E GUARUJÁ | K32: TERRAPLENAGEM | L32: 22.03.03
A33: 2.8 | B33: CB0002 | C33: TRANSPORTE DE MATERIAL DE 1ª/2ª CATEGORIA ATÉ 10 km | D33: m3 x km | E33: 247956.53 | H33: 1.43 | I33: =E33*H33 -> 354577.84 | J33: ACESSOS - LADO SANTOS E GUARUJÁ | K33: TERRAPLENAGEM | L33: 22.03.04
A34: 2.9 | C34: TRANSPORTE DE MATERIAL DE 1ª/2ª CATEGORIA ATÉ 15 km | D34: m3 x km | E34: 63019.43 | H34: 1.26 | I34: =E34*H34 -> 79404.482 | J34: ACESSOS - LADO SANTOS E GUARUJÁ | K34: TERRAPLENAGEM | L34: 22.03.05
A35: 2.10 | C35: TRANSPORTE DE MATERIAL DE LIMPEZA ATÉ 5 km | D35: m3 x km | E35: 35550.75 | H35: 1.93 | I35: =E35*H35 -> 68612.947 | J35: ACESSOS - LADO SANTOS E GUARUJÁ | K35: TERRAPLENAGEM | L35: 22.88.03.12.01
A36: 2.11 | C36: TRANSPORTE DE MATERIAL DE LIMPEZA ATÉ 10 km | D36: m3 x km | E36: 205980.75 | H36: 1.44 | I36: =E36*H36 -> 296612.28 | J36: ACESSOS - LADO SANTOS E GUARUJÁ | K36: TERRAPLENAGEM | L36: 22.88.03.12.02
A37: 2.12 | C37: TRANSPORTE DE MATERIAL DE LIMPEZA ATÉ 15 km | D37: m3 x km | E37: 17088.75 | H37: 1.3 | I37: =E37*H37 -> 22215.375 | J37: ACESSOS - LADO SANTOS E GUARUJÁ | K37: TERRAPLENAGEM | L37: 22.88.03.12.03
A38: 2.13 | C38: TRANSPORTE DE MATERIAL DE LIMPEZA ALÉM DE 15 km | D38: m3 x km | E38: 87885 | H38: 1.12 | I38: =E38*H38 -> 98431.2 | J38: ACESSOS - LADO SANTOS E GUARUJÁ | K38: TERRAPLENAGEM | L38: 22.88.03.12.04
A39: 2.14 | C39: COMPACTAÇÃO DE ATERRO MAIOR/IGUAL 95% PN | D39: m3 | E39: 30672 | H39: 3.01 | I39: =E39*H39 -> 92322.72 | J39: ACESSOS - LADO SANTOS E GUARUJÁ | K39: TERRAPLENAGEM | L39: 22.04.01
A40: 3 | C40: =K40 -> PAVIMENTAÇÃO | J40: ACESSOS - LADO SANTOS E GUARUJÁ | K40: PAVIMENTAÇÃO | L40: 23
A41: 3.1 | C41: ESPALHAMENTO / REGULARIZAÇÃO / COMPACTAÇÃO DE MATERIAL EM BOTA-FORA. | D41: m3 | E41: 39829.93 | H41: 2.21 | I41: =E41*H41 -> 88024.145 | J41: ACESSOS - LADO SANTOS E GUARUJÁ | K41: PAVIMENTAÇÃO | L41: 22.02.09
A42: 3.2 | C42: MELHORIA / PREPARO SUB-LEITO -100% EN | D42: m2 | E42: 106846.37 | H42: 1.14 | I42: =E42*H42 -> 121804.86 | J42: ACESSOS - LADO SANTOS E GUARUJÁ | K42: PAVIMENTAÇÃO | L42: 22.02.09
...

Sheet Original
B1: ID Primario | C1: ID | E1: SETOR | F1: GRUPO | G1: ITEM | H1: UNIDADE | I1: QUANT. | J1: PREÇO UNITÁRIO | K1: PREÇO TOTAL
B2: 1 | C2: 1 | D2: 21 | E2: ACESSOS - LADO SANTOS E GUARUJÁ | F2: SERVIÇOS PRELIMINARES
B3: 2 | C3: 1.1 | D3: 21.03.01 | E3: ACESSOS - LADO SANTOS E GUARUJÁ | F3: SERVIÇOS PRELIMINARES | G3: REMOÇÃO CERCA ARAME, INCLUSIVE TRANSPORTE | H3: m | I3: 400 | J3: 12.03 | K3: =I3*J3 -> 4812
B4: 3 | C4: 1.2 | D4: 21.03.02 | E4: ACESSOS - LADO SANTOS E GUARUJÁ | F4: SERVIÇOS PRELIMINARES | G4: REMOCAO DE DEFENSA METALICA SIMPLES | H4: m | I4: 200 | J4: 43.91 | K4: =I4*J4 -> 8782
B5: 4 | C5: 1.3 | D5: 21.03.08 | E5: ACESSOS - LADO SANTOS E GUARUJÁ | F5: SERVIÇOS PRELIMINARES | G5: REMOÇÃO E TRANSPORTE DE GUIA PRÉ-MOLDADA | H5: m | I5: 18670.46 | J5: 17.64 | K5: =I5*J5 -> 329346.91
B6: 5 | C6: 1.4 | D6: 21.88.0.,01 | E6: ACESSOS - LADO SANTOS E GUARUJÁ | F6: SERVIÇOS PRELIMINARES | G6: DEMOLIÇÃO DE CONCRETO ARMADO | H6: m3 | I6: 39039.41 | J6: 294.37 | K6: =I6*J6 -> 11492031
B7: 6 | C7: 1.5 | D7: 21.88.05.02 | E7: ACESSOS - LADO SANTOS E GUARUJÁ | F7: SERVIÇOS PRELIMINARES | G7: DEMOLIÇÃO DE CONCRETO SIMPLES | H7: m3 | I7: 63709.51 | J7: 154.29 | K7: =(I7*J7)-0.008 -> 9829740.3
B8: 7 | C8: 1.6 | D8: 21.88.05.05 | E8: ACESSOS - LADO SANTOS E GUARUJÁ | F8: SERVIÇOS PRELIMINARES | G8: DEMOLIÇÃO DE EDIFICAÇÃO EM ALVENARIA | H8: m2 | I8: 66412.68 | J8: 35.6 | K8: =I8*J8 -> 2364291.4
B9: 8 | C9: 1.7 | D9: 21.88.05.06 | E9: ACESSOS - LADO SANTOS E GUARUJÁ | F9: SERVIÇOS PRELIMINARES | G9: DEMOLIÇÃO DE EDIFICAÇÃO EM MADEIRA | H9: m2 | I9: 34516.27 | J9: 13.19 | K9: =I9*J9 -> 455269.6
B10: 9 | C10: 1.8 | D10: 21.88.05.07 | E10: ACESSOS - LADO SANTOS E GUARUJÁ | F10: SERVIÇOS PRELIMINARES | G10: DEMOLIÇÃO DE PAVIMENTO FLEXIVEL | H10: m3 | I10: 41618.81 | J10: 18.52 | K10: =I10*J10 -> 770780.36
B11: 10 | C11: 1.9 | D11: 21.88.19.01 | E11: ACESSOS - LADO SANTOS E GUARUJÁ | F11: SERVIÇOS PRELIMINARES | G11: MURO DE FECHAMENTO COM PLACAS E MOURÕES PRÉ-MOLDADO H=2,00 m | H11: m | I11: 100 | J11: 125.96 | K11: =I11*J11 -> 12596
B12: 11 | C12: 1.10 | D12: 21.88.19.08.03 | E12: ACESSOS - LADO SANTOS E GUARUJÁ | F12: SERVIÇOS PRELIMINARES | G12: TRANSPORTE DE MATERIAL CLASSE IIA e IIB PARA BOTA-FORA ESPECIAL | H12: ton x km | I12: 7813575.8 | J12: 1.24 | K12: =I12*J12 -> 9688834
B13: 12 | C13: 1.11 | D13: 21.88.20.01 | E13: ACESSOS - LADO SANTOS E GUARUJÁ | F13: SERVIÇOS PRELIMINARES | G13: BRITAGEM DE MATERIAL DE DEMOLIÇÃO | H13: m3 | I13: 101234.38 | J13: 50.86 | K13: =I13*J13 -> 5148780.6
B14: 13 | C14: 1.12 | D14: 21.88.21.02 | E14: ACESSOS - LADO SANTOS E GUARUJÁ | F14: SERVIÇOS PRELIMINARES | G14: DEPOSIÇÃO DE MATERIAL CLASSE IIA, EM BOTA-FORA ESPECIAL | H14: ton | I14: 151405.85 | J14: 94.5 | K14: =I14*J14 -> 14307853
B15: 14 | C15: 1.13 | D15: 21.88.21.03 | E15: ACESSOS - LADO SANTOS E GUARUJÁ | F15: SERVIÇOS PRELIMINARES | G15: DEPOSIÇÃO DE MATERIAL CLASSE IIB, EM BOTA-FORA ESPECIAL | H15: ton | I15: 151401.71 | J15: 67.5 | K15: =I15*J15 -> 10219615
B16: 15 | C16: 1.14 | D16: 22.88.03.03 | E16: ACESSOS - LADO SANTOS E GUARUJÁ | F16: SERVIÇOS PRELIMINARES | G16: TRANSPORTE DE MATERIAL DE DEMOLIÇÃO ATÉ 5 KM | H16: m3 x km | I16: 506171.91 | J16: 1.71 | K16: =I16*J16 -> 865553.97
B17: 16 | C17: 2 | D17: 22 | E17: ACESSOS - LADO SANTOS E GUARUJÁ | F17: TERRAPLENAGEM
B18: 17 | C18: 2.1 | D18: 22.01.01 | E18: ACESSOS - LADO SANTOS E GUARUJÁ | F18: TERRAPLENAGEM | G18: LIMPEZA ÁRVORES DE TERRENO SEM DESTOCAMENTO DE ÁRVORES | H18: m2 | I18: 181263 | J18: 0.28 | K18: =I18*J18 -> 50753.64
B19: 18 | C19: 2.2 | D19: 22.02.01 | E19: ACESSOS - LADO SANTOS E GUARUJÁ | F19: TERRAPLENAGEM | G19: ESCAVAÇÃO E CARGA DE MATERIAL DE 1ª/2ª CATEGORIA | H19: m3 | I19: 49049.95 | J19: 4.9 | K19: =I19*J19 -> 240344.76
B20: 19 | C20: 2.3 | D20: 22.02.02 | E20: ACESSOS - LADO SANTOS E GUARUJÁ | F20: TERRAPLENAGEM | G20: ESCAVAÇÃO E CARGA DE MATERIAL DE 2ª CATEGORIA COM RIPPER | H20: m3 | I20: 691.55 | J20: 5.44 | K20: =I20*J20 -> 3762.032
B21: 20 | C21: 2.4 | D21: 22.02.06 | E21: ACESSOS - LADO SANTOS E GUARUJÁ | F21: TERRAPLENAGEM | G21: CARGA DE MATERIAL DE LIMPEZA | H21: m3 | I21: 36252.6 | J21: 2.26 | K21: =I21*J21 -> 81930.876
B22: 21 | C22: 2.5 | D22: 22.03.01 | E22: ACESSOS - LADO SANTOS E GUARUJÁ | F22: TERRAPLENAGEM | G22: TRANSPORTE DE MATERIAL DE 1ª/2ª CATEGORIA ATÉ 1 km | H22: m3 x km | I22: 729.26 | J22: 3.74 | K22: =I22*J22 -> 2727.4324
B23: 22 | C23: 2.6 | D23: 22.03.02 | E23: ACESSOS - LADO SANTOS E GUARUJÁ | F23: TERRAPLENAGEM | G23: TRANSPORTE DE MATERIAL DE 1ª/2ª CATEGORIA ATÉ 2 km | H23: m3 x km | I23: 2187.76 | J23: 2.2 | K23: =I23*J23 -> 4813.072
B24: 23 | C24: 2.7 | D24: 22.03.03 | E24: ACESSOS - LADO SANTOS E GUARUJÁ | F24: TERRAPLENAGEM | G24: TRANSPORTE DE MATERIAL DE 1ª/2ª CATEGORIA ATÉ 5 km | H24: m3 x km | I24: 3000.93 | J24: 1.71 | K24: =I24*J24 -> 5131.5903
B25: 24 | C25: 2.8 | D25: 22.03.04 | E25: ACESSOS - LADO SANTOS E GUARUJÁ | F25: TERRAPLENAGEM | G25: TRANSPORTE DE MATERIAL DE 1ª/2ª CATEGORIA ATÉ 10 km | H25: m3 x km | I25: 247956.53 | J25: 1.43 | K25: =I25*J25 -> 354577.84
B26: 25 | C26: 2.9 | D26: 22.03.05 | E26: ACESSOS - LADO SANTOS E GUARUJÁ | F26: TERRAPLENAGEM | G26: TRANSPORTE DE MATERIAL DE 1ª/2ª CATEGORIA ATÉ 15 km | H26: m3 x km | I26: 63019.43 | J26: 1.26 | K26: =I26*J26 -> 79404.482
B27: 26 | C27: 2.10 | D27: 22.88.03.12.01 | E27: ACESSOS - LADO SANTOS E GUARUJÁ | F27: TERRAPLENAGEM | G27: TRANSPORTE DE MATERIAL DE LIMPEZA ATÉ 5 km | H27: m3 x km | I27: 35550.75 | J27: 1.93 | K27: =I27*J27 -> 68612.947
B28: 27 | C28: 2.11 | D28: 22.88.03.12.02 | E28: ACESSOS - LADO SANTOS E GUARUJÁ | F28: TERRAPLENAGEM | G28: TRANSPORTE DE MATERIAL DE LIMPEZA ATÉ 10 km | H28: m3 x km | I28: 205980.75 | J28: 1.44 | K28: =I28*J28 -> 296612.28
B29: 28 | C29: 2.12 | D29: 22.88.03.12.03 | E29: ACESSOS - LADO SANTOS E GUARUJÁ | F29: TERRAPLENAGEM | G29: TRANSPORTE DE MATERIAL DE LIMPEZA ATÉ 15 km | H29: m3 x km | I29: 17088.75 | J29: 1.3 | K29: =I29*J29 -> 22215.375
... B31: 30 | C31: 2.14 | D31: 22.04.01 | E31: ACESSOS - LADO SANTOS E GUARUJÁ | F31: TERRAPLENAGEM | G31: COMPACTAÇÃO DE ATERRO MAIOR/IGUAL 95% PN | H31: m3 | I31: 30672 | J31: 3.01 | K31: =I31*J31 -> 92322.72
B32: 31 | C32: 3 | D32: 23 | E32: ACESSOS - LADO SANTOS E GUARUJÁ | F32: PAVIMENTAÇÃO
B33: 32 | C33: 3.1 | D33: 22.02.09 | E33: ACESSOS - LADO SANTOS E GUARUJÁ | F33: PAVIMENTAÇÃO | G33: ESPALHAMENTO / REGULARIZAÇÃO / COMPACTAÇÃO DE MATERIAL EM BOTA-FORA. | H33: m3 | I33: 39829.93 | J33: 2.21 | K33: =I33*J33 -> 88024.145
B34: 33 | C34: 3.2 | D34: 22.02.09 | E34: ACESSOS - LADO SANTOS E GUARUJÁ | F34: PAVIMENTAÇÃO | G34: MELHORIA / PREPARO SUB-LEITO -100% EN | H34: m2 | I34: 106846.37 | J34: 1.14 | K34: =I34*J34 -> 121804.86
B35: 34 | C35: 3.3 | D35: 23.04.03.01 | E35: ACESSOS - LADO SANTOS E GUARUJÁ | F35: PAVIMENTAÇÃO | G35: SUB-BASE OU BASE BRITA GRADUADA SIMPLES | H35: m3 | I35: 21323.73 | J35: 168.38 | K35: =I35*J35 -> 3590489.7
B36: 35 | C36: 3.4 | D36: 23.04.03.04 | E36: ACESSOS - LADO SANTOS E GUARUJÁ | F36: PAVIMENTAÇÃO | G36: SUB-BASE OU BASE DE PEDRA RACHÃO | H36: m3 | I36: 48590.87 | J36: 168.04 | K36: =I36*J36 -> 8165209.8
B37: 36 | C37: 3.5 | D37: 23.04.04.04 | E37: ACESSOS - LADO SANTOS E GUARUJÁ | F37: PAVIMENTAÇÃO | G37: SUB-BASE OU BASE BRITA GRADUADA COM CIMENTO 4%VOL | H37: m3 | I37: 23047.05 | J37: 208.16 | K37: =I37*J37 -> 4797473.9
B38: 37 | C38: 3.6 | D38: 23.05.01 | E38: ACESSOS - LADO SANTOS E GUARUJÁ | F38: PAVIMENTAÇÃO | G38: IMPRIMADURA BETUMINOSA IMPERMEABILIZANTE | H38: m2 | I38: 127597.58 | J38: 3.42 | K38: =I38*J38 -> 436383.72
B39: 38 | C39: 3.7 | D39: 23.05.02 | E39: ACESSOS - LADO SANTOS E GUARUJÁ | F39: PAVIMENTAÇÃO | G39: IMPRIMADURA BETUMINOSA LIGANTE | H39: m2 | I39: 320347.81 | J39: 1.32 | K39: =I39*J39 -> 422859.11
B40: 39 | C40: 3.8 | D40: 23.05.04 | E40: ACESSOS - LADO SANTOS E GUARUJÁ | F40: PAVIMENTAÇÃO | G40: IMPRIMADURA BETUMINOSA LIGANTE MODIFICADA COM POLÍMERO | H40: m2 | I40: 92170.2 | J40: 1.71 | K40: =I40*J40 -> 157611.04
B41: 40 | C41: 3.9 | D41: 23.08.02 | E41: ACESSOS - LADO SANTOS E GUARUJÁ | F41: PAVIMENTAÇÃO | G41: CONCRETO ASFÁLTICO USINADO A QUENTE BINDER - GRADUAÇÃO B COM DOP | H41: m3 | I41: 10071.28 | J41: 488.89 | K41: =I41*J41 -> 4923748.1
...

Sheet INSUMOS
A1: Planilha: 00011 - TUNEL SUBMERSO SIGMA P82
A3: Codigo | B3: Descricao | C3: Unid | D3: Qtde | E3: Qtde Improd | F3: Custo Unit | G3: Valor | H3: % | I3: % Acum. | J3: % s/ Tot | K3: % Acum
A4: IM1920 | B4: FORNECIMENTO DE AÇO CA-50, CORTADO E DOBRADO | C4: KG | D4: 57547713 | F4: 2.53 | G4: 1.4559571e+08 | H4: 18.45 | I4: 18.45 | J4: 10.18 | K4: 10.18
A5: IM1273 | B5: TUBO DE AÇO CARBONO Ø2M E CONECTORES - COMBWALL | C5: KG | D5: 18916320 | F5: 4.5 | G5: 85123438 | H5: 10.79 | I5: 29.24 | J5: 5.95 | K5: 16.13
A6: IM1102 | B6: CIMENTO PORTLAND CP III RS 40 | C6: T | D6: 251407.65 | F6: 314.55 | G6: 79080297 | H6: 10.02 | I6: 39.26 | J6: 5.53 | K6: 21.66
A7: IM0704 | B7: AREIA LAVADA | C7: M3 | D7: 529015.05 | F7: 85 | G7: 44966289 | H7: 5.7 | I7: 44.96 | J7: 3.14 | K7: 24.8
A8: IM1281 | B8: INJEÇÃO DE COLUNA JET GROUTING EM SOLO NATURAL, INDEPENDENTE DIAMETRO | C8: M3 | D8: 125288.41 | F8: 250 | G8: 31322102 | H8: 3.97 | I8: 48.93 | J8: 2.19 | K8: 26.99
A9: IM0201 | B9: CIMENTO PORTLAND CP II-32(A GRANEL) | C9: KG | D9: 75262873 | F9: 0.3 | G9: 22578862 | H9: 2.86 | I9: 51.79 | J9: 1.58 | K9: 28.57
A10: IM1916 | B10: INSTALAÇÃO DE CANTEIRO DE OBRAS | C10: GB | D10: 1 | F10: 21625344 | G10: 21625344 | H10: 2.74 | I10: 54.53 | J10: 1.51 | K10: 30.08
A11: IN0035 | B11: BRITA 1 | C11: M3 | D11: 268819.26 | F11: 75 | G11: 20161441 | H11: 2.55 | I11: 57.08 | J11: 1.41 | K11: 31.49
A12: IM1106 | B12: RACHÃO | C12: M3 | D12: 254314.48 | F12: 74 | G12: 18819271 | H12: 2.38 | I12: 59.46 | J12: 1.32 | K12: 32.81
A13: IM1931 | B13: MATERIAL CONSUMO DE CONSUMO COMBWALL | C13: KG | D13: 18008685 | F13: 0.91 | G13: 16387904 | H13: 2.08 | I13: 61.54 | J13: 1.15 | K13: 33.96
A14: IM1881 | B14: DRAGAGEM / REMOÇÃO DE MATERIAL MARINHO (PROFUNDIDADES DE 15,0 A 32,0 m), INCLUSIVE TRANSPORTE E DEPOSIÇÃO EM LOCAL APROPRIADO (POLIGONO DE DEPOSIÇÃO OCEANICA) | C14: M3 | D14: 138086.55 | F14: 117.26 | G14: 16192029 | H14: 2.05 | I14: 63.59 | J14: 1.13 | K14: 35.09
A15: IM0002 | B15: OLEO DIESEL | C15: L | D15: 7030663.7 | F15: 2.26 | G15: 15890003 | H15: 2.01 | I15: 65.6 | J15: 1.11 | K15: 36.2
... A806: IH1028 | B806: OPERATI MEZZI MARITIMI | C806: H | D806: 10.805211 | F806: 31.26 | G806: 0 | H806: 0 | I806: 100 | J806: 0 | K806: 13.67
A807: IE5084 | B807: MARINE EQUIPEMENT FOR DRAGAGEM - 15 | C807: H | D807: 7799.9894 | E807: 21.802 | F807: 25317.59 | G807: 1.9797871e+08 | H807: 43.66 | I807: 43.66 | J807: 13.84 | K807: 13.84
A808: IE0404 | B808: CAMINHÃO BASCULANTE 25 T | C808: H | D808: 325120.33 | E808: 790.662 | F808: 123.69 | G808: 40156777 | H808: 8.85 | I808: 52.51 | J808: 2.81 | K808: 16.65
A809: IE0427 | B809: CAMINHÃO BETONEIRA 8M³ | C809: H | D809: 84197.327 | E809: 370989.83 | F809: 144.41 | G809: 18022531 | H809: 3.97 | I809: 56.48 | J809: 1.26 | K809: 17.91
A810: IE5056 | B810: EQUIPAMENTO PARA INJEÇÃO DE JET GROUTING | C810: H | D810: 32640.431 | E810: 732.796 | F810: 534.83 | G810: 17611295 | H810: 3.88 | I810: 60.36 | J810: 1.23 | K810: 19.14
A811: IE5043 | B811: GRUPO DE ESCAVAÇÃO COM KELLY | C811: H | D811: 37613.307 | E811: 3313.294 | F811: 451.32 | G811: 16975641 | H811: 3.74 | I811: 64.1 | J811: 1.19 | K811: 20.33
A812: IE5087 | B812: MARINE EQUIPEMENT FOR LANCIAMENTO RACHAO | C812: H | D812: 3119.9993 | E812: 63.571 | F812: 4357 | G812: 13848748 | H812: 3.05 | I812: 67.15 | J812: 0.97 | K812: 21.3
A813: IE5089 | B813: MARINE EQUIPEMENT FOR DRAGAGEM E LANÇAMENTO DE AREIA | C813: H | D813: 2423.5741 | E813: 40.406 | F813: 5216.51 | G813: 12837439 | H813: 2.83 | I813: 69.98 | J813: 0.9 | K813: 22.2
A814: IE5080 | B814: CENTRAL DOSADORA DE CONCRETO | C814: H | D814: 15054.749 | F814: 803 | G814: 12088605 | H814: 2.67 | I814: 72.65 | J814: 0.84 | K814: 23.04
A815: IE5078 | B815: GRUPO DE EQUIPAMENTO HIDROFRESA | C815: H | D815: 9638.5207 | E815: 732.796 | F815: 1199.88 | G815: 11565103 | H815: 2.55 | I815: 75.2 | J815: 0.81 | K815: 23.85
A816: IE0201 | B816: COMPRESSOR DE AR - 295 PCM | C816: H | D816: 23000.485 | E816: 469887.15 | F816: 71.01 | G816: 8892589.9 | H816: 1.96 | I816: 77.16 | J816: 0.62 | K816: 24.47
A817: IE5075 | B817: CAMINHÃO DUMPER 25T | C817: H | D817: 102210.84 | E817: 31412.088 | F817: 70 | G817: 7153321.8 | H817: 1.58 | I817: 78.74 | J817: 0.5 | K817: 24.97
A818: IE5040 | B818: PÁ CARREGADEIRA W170ZB - 183 HP | C818: H | D818: 46177.857 | E818: 34117.54 | F818: 103.5 | G818: 6072382.6 | H818: 1.34 | I818: 80.08 | J818: 0.42 | K818: 25.39
A819: IE5083 | B819: MARINE EQUIPEMENT FOR COMBIWALL | C819: H | D819: 1596.508 | E819: 72.114 | F819: 3519.23 | G819: 5777115.5 | H819: 1.27 | I819: 81.35 | J819: 0.4 | K819: 25.79
A820: IE0406 | B820: CAMINHÃO PIPA 18.000 LT | C820: H | D820: 12271.396 | E820: 93265.525 | F820: 126.23 | G820: 5171144 | H820: 1.14 | I820: 82.49 | J820: 0.36 | K820: 26.15
A821: IE5064 | B821: GUINDASTE SOBRE PNEUS 30T | C821: H | D821: 34301.528 | E821: 474874.38 | F821: 150 | G821: 4972469.8 | H821: 1.1 | I821: 83.59 | J821: 0.35 | K821: 26.5
A822: IE5070 | B822: GUINDASTE SOBRE ESTEIRAS 100T | C822: H | D822: 10211.418 | E822: 1152.836 | F822: 460 | G822: 4697046.1 | H822: 1.04 | I822: 84.63 | J822: 0.33 | K822: 26.83
A823: IE5054 | B823: SONDA PERFURATRIZ | C823: H | D823: 24313.52 | E823: 138.08 | F823: 178.22 | G823: 4349222.6 | H823: 0.96 | I823: 85.59 | J823: 0.3 | K823: 27.13
A824: IE0147 | B824: USINA DE ASFALTO A QUENTE : CIFALI : CIFALI MAGNUM 120 - | C824: H | D824: 466.3802 | F824: 8223.76 | G824: 3835437.1 | H824: 0.85 | I824: 86.44 | J824: 0.27 | K824: 27.4
A825: IE5072 | B825: GUINDASTE SOBRE ESTEIRAS 250T | C825: H | D825: 6227.0418 | E825: 360.893 | F825: 600 | G825: 3783551.9 | H825: 0.83 | I825: 87.27 | J825: 0.26 | K825: 27.66
A826: IE5077 | B826: TORRE DE ILUMINAÇÃO | C826: H | D826: 184648.4 | E826: 386155.86 | F826: 20 | G826: 3605805 | H826: 0.8 | I826: 88.07 | J826: 0.25 | K826: 27.91
A827: IE5052 | B827: COMPRESSOR DE AR 21,9 M3/1' | C827: H | D827: 32390.86 | E827: 40116.798 | F827: 84.2 | G827: 3356917.2 | H827: 0.74 | I827: 88.81 | J827: 0.23 | K827: 28.14
A828: IE5026 | B828: CAMINHÃO MUNCK 5T | C828: H | D828: 10568.502 | E828: 71212.651 | F828: 101.24 | G828: 3262404.9 | H828: 0.72 | I828: 89.53 | J828: 0.23 | K828: 28.37
A829: IE5082 | B829: DRIVER MARINE EQUIPEMENT FOR DRAGAGEM | C829: H | D829: 42119.99 | E829: 209.884 | F829: 77 | G829: 3240738.2 | H829: 0.71 | I829: 90.24 | J829: 0.23 | K829: 28.6
A830: IE5045 | B830: DESARENADOR COMPLETO 200 M3/HR | C830: H | D830: 31102.471 | E830: 1441.297 | F830: 85.74 | G830: 2719913.3 | H830: 0.6 | I830: 90.84 | J830: 0.19 | K830: 28.79
A831: IE5091 | B831: MARTELLO VIBRO PER TUBI DI ACCIAIO + POWER PACK | C831: H | D831: 4620.8486 | E831: 1962.946 | F831: 500 | G831: 2341129.1 | H831: 0.52 | I831: 91.36 | J831: 0.16 | K831: 28.95
...

Sheet CPU AUX
