Workbook

Sheet Planilha1
A1: Objeto: | B1: EXECUÇÃO DE OBRAS DE REDES COLETORAS DE ESGOTO , COLETORES TRONCO, EEES E LINHAS DE RECALQUE DO SISTEMA DE ESGOTAMENTO SANITÁRIO NO MUNICÍPIO DE ITAPECERICA DA SERRA - UGR GUARAPIRANGA - UNSUL - MS
A3: PLANILHA DE ORÇAMENTO
A5: ITEM | B5: DESCRIÇÃO | C5: N.PRECO | D5: UN. MED. | E5: QUANT. | F5: PREÇO UNIT. | G5: TOTAL
A6: 01000000 | B6: EXECUÇÃO DE OBRAS PARA IMPLANTAÇÃO DE RCE,COLETORES TRONCO, EEES E LINHAS DE RECALQUE -MUNICIPIO DE ITAPECERICA DA SERRA
A7: 01010000 | B7: CANTEIRO DE OBRAS
A8: 01010001 | B8: INSTALAÇÃO DE CANTEIRO DE OBRAS TIPO I | C8: 355001 | D8: GB | E8: 1 | F8: =+VLOOKUP(C8,[1]Serviços!$C$6:$F$172,4,FALSE) -> 109000 | G8: =+ROUND(F8*E8,2) -> 109000
D9: Total do Grupo | G9: =+G8 -> 109000
A10: 01020000 | B10: MANUTENÇÃO DE CANTEIRO DE OBRAS
A11: 01020001 | B11: MANUTENÇÃO DO CANTEIRO DE OBRAS TIPO 1 | C11: 355002 | D11: MES | E11: 24 | F11: =+VLOOKUP(C11,[1]Serviços!$C$6:$F$172,4,FALSE) -> 22125 | G11: =+ROUND(F11*E11,2) -> 531000
D12: Total do Grupo | G12: =+G11 -> 531000
A13: 01030000 | B13: SERVIÇOS ESPECIALIZADOS REFERENTES AO PLANO DE GESTÃO AMBIENTAL, COMUNICAÇÃO E SÓCIO EDUCATIVO
A14: 01030001 | B14: PLANO DE AÇÕES SOCIO EDUCATIVA | C14: 355003 | D14: MES | E14: 24 | F14: =+VLOOKUP(C14,[1]Serviços!$C$6:$F$172,4,FALSE) -> 13424.94 | G14: =+ROUND(F14*E14,2) -> 322198.56
A15: 01030002 | B15: PLANO DE GESTÃO AMBIENTAL | C15: 355004 | D15: MES | E15: 24 | F15: =+VLOOKUP(C15,[1]Serviços!$C$6:$F$172,4,FALSE) -> 24144.08 | G15: =+ROUND(F15*E15,2) -> 579457.92
A16: 01030003 | B16: PLANO DE COMUNICAÇÃO SOCIO EDUCATIVA | C16: 355005 | D16: MES | E16: 24 | F16: =+VLOOKUP(C16,[1]Serviços!$C$6:$F$172,4,FALSE) -> 13424.94 | G16: =+ROUND(F16*E16,2) -> 322198.56
D17: Total do Grupo | G17: =SUM(G14:G16) -> 1223855
A18: 01040000 | B18: REDES COLETORAS ITAPECERICA DA SERRA
A19: 01040100 | B19: LOCAÇÃO E CADASTRO
A20: 01040101 | B20: LOCAÇÃO DE REDES DE ESGOTOS (ATÉ DIAM. 500MM) | C20: 020201 | D20: M | E20: 25000 | F20: =+VLOOKUP(C20,[1]Serviços!$C$6:$F$172,4,FALSE) -> 0.65 | G20: =+ROUND(F20*E20,2) -> 16250
A21: 01040102 | B21: CADASTRO DE REDES | C21: 020205 | D21: M | E21: 25000 | F21: =+VLOOKUP(C21,[1]Serviços!$C$6:$F$172,4,FALSE) -> 1.64 | G21: =+ROUND(F21*E21,2) -> 41000
D22: Total do Grupo | G22: =SUM(G20:G21) -> 57250
A23: 01050000 | B23: SERVIÇOS PRELIMINARES
A24: 01050100 | B24: TRANSITO E SEGURANÇA
A25: 01050101 | B25: SINALIZAÇÃO LUMINOSA PARA OBRAS | C25: 030101 | D25: M | E25: 25000 | F25: =+VLOOKUP(C25,[1]Serviços!$C$6:$F$172,4,FALSE) -> 2.41 | G25: =+ROUND(F25*E25,2) -> 60250
A26: 01050102 | B26: TAPUME CONTÍNUO EM CHAPAS DE MADEIRA | C26: 030110 | D26: M | E26: 25000 | F26: =+VLOOKUP(C26,[1]Serviços!$C$6:$F$172,4,FALSE) -> 4.34 | G26: =+ROUND(F26*E26,2) -> 108500
A27: 01050200 | B27: PASSADIÇOS E TRAVESSIAS
A28: 01050201 | B28: PASSADIÇOS DE MADEIRA PARA PEDESTRES | C28: 030201 | D28: M2 | E28: 400 | F28: =+VLOOKUP(C28,[1]Serviços!$C$6:$F$172,4,FALSE) -> 62.99 | G28: =+ROUND(F28*E28,2) -> 25196
A29: 01050202 | B29: PASSADIÇOS DE MADEIRA PARA VEÍCULOS | C29: 030205 | D29: M2 | E29: 1200 | F29: =+VLOOKUP(C29,[1]Serviços!$C$6:$F$172,4,FALSE) -> 56.19 | G29: =+ROUND(F29*E29,2) -> 67428
A30: 01050203 | B30: PASSADIÇOS DE CHAPA METÁLICA PARA VEÍCULOS | C30: 030206 | D30: M2 | E30: 300 | F30: =+VLOOKUP(C30,[1]Serviços!$C$6:$F$172,4,FALSE) -> 88.18 | G30: =+ROUND(F30*E30,2) -> 26454
A31: 01050300 | B31: SUSTENTAÇÃO DE ESTRUTURAS
A32: 01050301 | B32: ESCORAMENTO DE POSTES | C32: 030301 | D32: UN | E32: 20 | F32: =+VLOOKUP(C32,[1]Serviços!$C$6:$F$172,4,FALSE) -> 84.06 | G32: =+ROUND(F32*E32,2) -> 1681.2
A33: 01050302 | B33: SUSTENTAÇÃO DE TUBULAÇÕES EXISTENTES - PRANCHAS DE PEROBA | C33: 030302 | D33: M3 | E33: 10 | F33: =+VLOOKUP(C33,[1]Serviços!$C$6:$F$172,4,FALSE) -> 1718.52 | G33: =+ROUND(F33*E33,2) -> 17185.2
A34: 01050303 | B34: SUSTENTAÇÃO DE TUBULAÇÕES EXISTENTES - PERFIS METÁLICOS | C34: 030303 | D34: T | E34: 8 | F34: =+VLOOKUP(C34,[1]Serviços!$C$6:$F$172,4,FALSE) -> 928.65 | G34: =+ROUND(F34*E34,2) -> 7429.2
A35: 01050400 | B35: DESMATAMENTO E LIMPEZA
A36: 01050401 | B36: CORTE DE ÁRVORE COM DESTOCAMENTO | C36: 030501 | D36: UN | E36: 10 | F36: =+VLOOKUP(C36,[1]Serviços!$C$6:$F$172,4,FALSE) -> 14.46 | G36: =+ROUND(F36*E36,2) -> 144.6
A37: 01050402 | B37: ROÇADA E CAPINA | C37: 030502 | D37: M2 | E37: 180 | F37: =+VLOOKUP(C37,[1]Serviços!$C$6:$F$172,4,FALSE) -> 2.07 | G37: =+ROUND(F37*E37,2) -> 372.6
D38: Total do Grupo | G38: =SUM(G25:G37) -> 314640.8
A39: 01060000 | B39: MOVIMENTO DE TERRA
A40: 01060100 | B40: ESCAVAÇÃO EM GERAL
A41: 01060101 | B41: RASPAGEM DA CAMADA SUPERFICIAL | C41: 040101 | D41: M2 | E41: 180 | F41: =+VLOOKUP(C41,[1]Serviços!$C$6:$F$172,4,FALSE) -> 1.18 | G41: =+ROUND(F41*E41,2) -> 212.4
A42: 01060102 | B42: ESCAVAÇÃO EM JAZIDA DE SOLO | C42: 040104 | D42: M3 | E42: 17500 | F42: =+VLOOKUP(C42,[1]Serviços!$C$6:$F$172,4,FALSE) -> 7.69 | G42: =+ROUND(F42*E42,2) -> 134575
...
